<?xml version="1.0"?>

<!--
Proj515

Alpha robot urdf test

-->

<robot name ="alpha">

  <link name="base_link">
    <visual>
      <origin rpy="1.57 0 1.57" xyz="0 0 0"/>
      <geometry>
        <mesh filename="file:/home/olly/proj_ws/src/alpha_urdf/src/urdf_base.stl" scale="0.001 0.001 0.001"/>
      </geometry>
    </visual>
  </link>

  <link name="right_wheel">
    <visual>
      <origin rpy="0 0 1.57" xyz="0 0 0"/>
      <geometry>
        <mesh filename="file:/home/olly/proj_ws/src/alpha_urdf/src/urdf_wheel.stl" scale="0.001 0.001 0.001"/>
      </geometry>
    </visual>
  </link>

  <link name="left_wheel">
    <visual>
      <origin rpy="0 0 -1.57" xyz="0 0 0"/>
      <geometry>
        <mesh filename="file:/home/olly/proj_ws/src/alpha_urdf/src/urdf_wheel.stl" scale="0.001 0.001 0.001"/>
      </geometry>
    </visual>
  </link>

  <link name="laser">
    <visual>
      <origin rpy="1.57 0 0" xyz="0 0 0"/>
      <geometry>
        <mesh filename="file:/home/olly/proj_ws/src/alpha_urdf/src/urdf_lidar.stl" scale="0.001 0.001 0.001"/>
      </geometry>
    </visual>
  </link>

  <joint name="base_right_wheel" type="continuous">
    <axis xyz="0 1 0"/>
    <parent link="base_link"/>
    <child link="right_wheel"/>
    <origin rpy = "0 0 0" xyz = "0 -0.147852 0.039"/>
  </joint>

  <joint name="base_left_wheel" type="continuous">
    <axis xyz="0 1 0"/>
    <parent link="base_link"/>
    <child link="left_wheel"/>
    <origin rpy = "0 0 0" xyz = "0 0.147852 0.039"/>
  </joint>

  <joint name="base_laser_joint" type="fixed">
    <axis xyz="1 0 0"/>
    <parent link="base_link"/>
    <child link="laser"/>
    <!-- old laser pos <origin rpy = "0 0 0" xyz = "0.203092 0 0.157933"/> -->
    <origin rpy = "0 0 0" xyz = "0.152993 0 0.388138"/>
  </joint>



</robot>

